Failure # 1 (occurred at 2024-07-17_21-05-46)
Traceback (most recent call last):
  File "c:\Users\Ody\anaconda3\envs\test\lib\site-packages\ray\tune\execution\ray_trial_executor.py", line 1276, in get_next_executor_event
    future_result = ray.get(ready_future)
  File "c:\Users\Ody\anaconda3\envs\test\lib\site-packages\ray\_private\client_mode_hook.py", line 105, in wrapper
    return func(*args, **kwargs)
  File "c:\Users\Ody\anaconda3\envs\test\lib\site-packages\ray\_private\worker.py", line 2382, in get
    raise value
ray.exceptions.RayActorError: The actor died because of an error raised in its creation task, [36mray::A2C.__init__()[39m (pid=15904, ip=127.0.0.1, repr=A2C)
  File "python\ray\_raylet.pyx", line 857, in ray._raylet.execute_task
  File "python\ray\_raylet.pyx", line 861, in ray._raylet.execute_task
  File "python\ray\_raylet.pyx", line 803, in ray._raylet.execute_task.function_executor
  File "c:\Users\Ody\anaconda3\envs\test\lib\site-packages\ray\_private\function_manager.py", line 674, in actor_method_executor
    return method(__ray_actor, *args, **kwargs)
  File "c:\Users\Ody\anaconda3\envs\test\lib\site-packages\ray\util\tracing\tracing_helper.py", line 466, in _resume_span
    return method(self, *_args, **_kwargs)
  File "c:\Users\Ody\anaconda3\envs\test\lib\site-packages\ray\rllib\algorithms\algorithm.py", line 445, in __init__
    super().__init__(
  File "c:\Users\Ody\anaconda3\envs\test\lib\site-packages\ray\tune\trainable\trainable.py", line 169, in __init__
    self.setup(copy.deepcopy(self.config))
  File "c:\Users\Ody\anaconda3\envs\test\lib\site-packages\ray\util\tracing\tracing_helper.py", line 466, in _resume_span
    return method(self, *_args, **_kwargs)
  File "c:\Users\Ody\anaconda3\envs\test\lib\site-packages\ray\rllib\algorithms\a2c\a2c.py", line 158, in setup
    super().setup(config)
  File "c:\Users\Ody\anaconda3\envs\test\lib\site-packages\ray\rllib\algorithms\algorithm.py", line 571, in setup
    self.workers = WorkerSet(
  File "c:\Users\Ody\anaconda3\envs\test\lib\site-packages\ray\rllib\evaluation\worker_set.py", line 170, in __init__
    self._setup(
  File "c:\Users\Ody\anaconda3\envs\test\lib\site-packages\ray\rllib\evaluation\worker_set.py", line 260, in _setup
    self._local_worker = self._make_worker(
  File "c:\Users\Ody\anaconda3\envs\test\lib\site-packages\ray\rllib\evaluation\worker_set.py", line 946, in _make_worker
    worker = cls(
  File "c:\Users\Ody\anaconda3\envs\test\lib\site-packages\ray\rllib\evaluation\rollout_worker.py", line 607, in __init__
    self.env = env_creator(copy.deepcopy(self.env_context))
  File "C:\Users\Ody\AppData\Local\Temp\ipykernel_19588\2891194472.py", line 8, in <lambda>
NameError: name 'prudent_train_env' is not defined

