Failure # 1 (occurred at 2024-03-29_15-05-03)
Traceback (most recent call last):
  File "/usr/local/lib/python3.10/dist-packages/ray/tune/execution/ray_trial_executor.py", line 1276, in get_next_executor_event
    future_result = ray.get(ready_future)
  File "/usr/local/lib/python3.10/dist-packages/ray/_private/client_mode_hook.py", line 105, in wrapper
    return func(*args, **kwargs)
  File "/usr/local/lib/python3.10/dist-packages/ray/_private/worker.py", line 2382, in get
    raise value
ray.exceptions.RayActorError: The actor died because of an error raised in its creation task, [36mray::A2C.__init__()[39m (pid=162006, ip=195.251.234.24, repr=A2C)
  File "/usr/local/lib/python3.10/dist-packages/ray/rllib/algorithms/algorithm.py", line 445, in __init__
    super().__init__(
  File "/usr/local/lib/python3.10/dist-packages/ray/tune/trainable/trainable.py", line 169, in __init__
    self.setup(copy.deepcopy(self.config))
  File "/usr/local/lib/python3.10/dist-packages/ray/rllib/algorithms/a2c/a2c.py", line 158, in setup
    super().setup(config)
  File "/usr/local/lib/python3.10/dist-packages/ray/rllib/algorithms/algorithm.py", line 571, in setup
    self.workers = WorkerSet(
  File "/usr/local/lib/python3.10/dist-packages/ray/rllib/evaluation/worker_set.py", line 170, in __init__
    self._setup(
  File "/usr/local/lib/python3.10/dist-packages/ray/rllib/evaluation/worker_set.py", line 260, in _setup
    self._local_worker = self._make_worker(
  File "/usr/local/lib/python3.10/dist-packages/ray/rllib/evaluation/worker_set.py", line 946, in _make_worker
    worker = cls(
  File "/usr/local/lib/python3.10/dist-packages/ray/rllib/evaluation/rollout_worker.py", line 607, in __init__
    self.env = env_creator(copy.deepcopy(self.env_context))
  File "/tmp/ipykernel_160089/2575632837.py", line 7, in <lambda>
NameError: name 'prudent_train_env' is not defined

